[rank: 0] Seed set to 0
'(MaxRetryError("HTTPSConnectionPool(host='huggingface.co', port=443): Max retries exceeded with url: /facebook/dinov3-vits16-pretrain-lvd1689m/resolve/main/config.json (Caused by NewConnectionError('<urllib3.connection.HTTPSConnection object at 0x7fbe6cc0f0e0>: Failed to establish a new connection: [Errno 101] Network is unreachable'))"), '(Request ID: 6865da16-eae8-481f-86d5-a95a5d42e3bc)')' thrown while requesting HEAD https://huggingface.co/facebook/dinov3-vits16-pretrain-lvd1689m/resolve/main/config.json
Retrying in 1s [Retry 1/5].
'(MaxRetryError("HTTPSConnectionPool(host='huggingface.co', port=443): Max retries exceeded with url: /facebook/dinov3-vits16-pretrain-lvd1689m/resolve/main/config.json (Caused by NewConnectionError('<urllib3.connection.HTTPSConnection object at 0x7fbe6e924690>: Failed to establish a new connection: [Errno 101] Network is unreachable'))"), '(Request ID: 4c6ba94f-b32c-4db2-b761-fea5646dcaa6)')' thrown while requesting HEAD https://huggingface.co/facebook/dinov3-vits16-pretrain-lvd1689m/resolve/main/config.json
Retrying in 2s [Retry 2/5].
'(MaxRetryError("HTTPSConnectionPool(host='huggingface.co', port=443): Max retries exceeded with url: /facebook/dinov3-vits16-pretrain-lvd1689m/resolve/main/config.json (Caused by NewConnectionError('<urllib3.connection.HTTPSConnection object at 0x7fbe6e925450>: Failed to establish a new connection: [Errno 101] Network is unreachable'))"), '(Request ID: 94988d2b-8043-44a9-a652-e6c7e997cff3)')' thrown while requesting HEAD https://huggingface.co/facebook/dinov3-vits16-pretrain-lvd1689m/resolve/main/config.json
Retrying in 4s [Retry 3/5].
'(MaxRetryError("HTTPSConnectionPool(host='huggingface.co', port=443): Max retries exceeded with url: /facebook/dinov3-vits16-pretrain-lvd1689m/resolve/main/config.json (Caused by NewConnectionError('<urllib3.connection.HTTPSConnection object at 0x7fbe6e925bd0>: Failed to establish a new connection: [Errno 101] Network is unreachable'))"), '(Request ID: af405e0e-107f-4352-8f7e-21408eb0e19d)')' thrown while requesting HEAD https://huggingface.co/facebook/dinov3-vits16-pretrain-lvd1689m/resolve/main/config.json
Retrying in 8s [Retry 4/5].
'(MaxRetryError("HTTPSConnectionPool(host='huggingface.co', port=443): Max retries exceeded with url: /facebook/dinov3-vits16-pretrain-lvd1689m/resolve/main/config.json (Caused by NewConnectionError('<urllib3.connection.HTTPSConnection object at 0x7fbe6e925e50>: Failed to establish a new connection: [Errno 101] Network is unreachable'))"), '(Request ID: 5b34bc9a-5a20-4ae4-98d2-fea1bdc36457)')' thrown while requesting HEAD https://huggingface.co/facebook/dinov3-vits16-pretrain-lvd1689m/resolve/main/config.json
Retrying in 8s [Retry 5/5].
'(MaxRetryError("HTTPSConnectionPool(host='huggingface.co', port=443): Max retries exceeded with url: /facebook/dinov3-vits16-pretrain-lvd1689m/resolve/main/config.json (Caused by NewConnectionError('<urllib3.connection.HTTPSConnection object at 0x7fbe6e9260d0>: Failed to establish a new connection: [Errno 101] Network is unreachable'))"), '(Request ID: 7038eaad-c5a6-4308-9c0c-7dd1d2b0a137)')' thrown while requesting HEAD https://huggingface.co/facebook/dinov3-vits16-pretrain-lvd1689m/resolve/main/config.json
'(MaxRetryError("HTTPSConnectionPool(host='huggingface.co', port=443): Max retries exceeded with url: /facebook/dinov3-vits16-pretrain-lvd1689m/resolve/main/config.json (Caused by NewConnectionError('<urllib3.connection.HTTPSConnection object at 0x7fbe6e926ad0>: Failed to establish a new connection: [Errno 101] Network is unreachable'))"), '(Request ID: fb369caf-bf65-461c-8c69-48a6b482e2e8)')' thrown while requesting HEAD https://huggingface.co/facebook/dinov3-vits16-pretrain-lvd1689m/resolve/main/config.json
Retrying in 1s [Retry 1/5].
'(MaxRetryError("HTTPSConnectionPool(host='huggingface.co', port=443): Max retries exceeded with url: /facebook/dinov3-vits16-pretrain-lvd1689m/resolve/main/config.json (Caused by NewConnectionError('<urllib3.connection.HTTPSConnection object at 0x7fbe6e926c10>: Failed to establish a new connection: [Errno 101] Network is unreachable'))"), '(Request ID: 6494d3cb-8503-49a8-8326-21cf624dd5e0)')' thrown while requesting HEAD https://huggingface.co/facebook/dinov3-vits16-pretrain-lvd1689m/resolve/main/config.json
Retrying in 2s [Retry 2/5].
'(MaxRetryError("HTTPSConnectionPool(host='huggingface.co', port=443): Max retries exceeded with url: /facebook/dinov3-vits16-pretrain-lvd1689m/resolve/main/config.json (Caused by NewConnectionError('<urllib3.connection.HTTPSConnection object at 0x7fbe6e926e90>: Failed to establish a new connection: [Errno 101] Network is unreachable'))"), '(Request ID: 875d3cb0-7b49-456d-970f-666795cafd4f)')' thrown while requesting HEAD https://huggingface.co/facebook/dinov3-vits16-pretrain-lvd1689m/resolve/main/config.json
Retrying in 4s [Retry 3/5].
'(MaxRetryError("HTTPSConnectionPool(host='huggingface.co', port=443): Max retries exceeded with url: /facebook/dinov3-vits16-pretrain-lvd1689m/resolve/main/config.json (Caused by NewConnectionError('<urllib3.connection.HTTPSConnection object at 0x7fbe6e927110>: Failed to establish a new connection: [Errno 101] Network is unreachable'))"), '(Request ID: db571dd1-05d6-4f55-854a-761d3d30b525)')' thrown while requesting HEAD https://huggingface.co/facebook/dinov3-vits16-pretrain-lvd1689m/resolve/main/config.json
Retrying in 8s [Retry 4/5].
'(MaxRetryError("HTTPSConnectionPool(host='huggingface.co', port=443): Max retries exceeded with url: /facebook/dinov3-vits16-pretrain-lvd1689m/resolve/main/config.json (Caused by NewConnectionError('<urllib3.connection.HTTPSConnection object at 0x7fbe6e927390>: Failed to establish a new connection: [Errno 101] Network is unreachable'))"), '(Request ID: e43172a5-7396-43c1-bc6d-279091873e70)')' thrown while requesting HEAD https://huggingface.co/facebook/dinov3-vits16-pretrain-lvd1689m/resolve/main/config.json
Retrying in 8s [Retry 5/5].
'(MaxRetryError("HTTPSConnectionPool(host='huggingface.co', port=443): Max retries exceeded with url: /facebook/dinov3-vits16-pretrain-lvd1689m/resolve/main/config.json (Caused by NewConnectionError('<urllib3.connection.HTTPSConnection object at 0x7fbe6e927610>: Failed to establish a new connection: [Errno 101] Network is unreachable'))"), '(Request ID: 8da892b8-13f0-44e9-9d5c-4e0d72a5ee45)')' thrown while requesting HEAD https://huggingface.co/facebook/dinov3-vits16-pretrain-lvd1689m/resolve/main/config.json
Traceback (most recent call last):
  File "/lustrefs/disk/home/pjakkraw/workspace/eomt/.venv/lib/python3.13/site-packages/urllib3/connection.py", line 198, in _new_conn
    sock = connection.create_connection(
        (self._dns_host, self.port),
    ...<2 lines>...
        socket_options=self.socket_options,
    )
  File "/lustrefs/disk/home/pjakkraw/workspace/eomt/.venv/lib/python3.13/site-packages/urllib3/util/connection.py", line 85, in create_connection
    raise err
  File "/lustrefs/disk/home/pjakkraw/workspace/eomt/.venv/lib/python3.13/site-packages/urllib3/util/connection.py", line 73, in create_connection
    sock.connect(sa)
    ~~~~~~~~~~~~^^^^
OSError: [Errno 101] Network is unreachable

The above exception was the direct cause of the following exception:

Traceback (most recent call last):
  File "/lustrefs/disk/home/pjakkraw/workspace/eomt/.venv/lib/python3.13/site-packages/urllib3/connectionpool.py", line 787, in urlopen
    response = self._make_request(
        conn,
    ...<10 lines>...
        **response_kw,
    )
  File "/lustrefs/disk/home/pjakkraw/workspace/eomt/.venv/lib/python3.13/site-packages/urllib3/connectionpool.py", line 488, in _make_request
    raise new_e
  File "/lustrefs/disk/home/pjakkraw/workspace/eomt/.venv/lib/python3.13/site-packages/urllib3/connectionpool.py", line 464, in _make_request
    self._validate_conn(conn)
    ~~~~~~~~~~~~~~~~~~~^^^^^^
  File "/lustrefs/disk/home/pjakkraw/workspace/eomt/.venv/lib/python3.13/site-packages/urllib3/connectionpool.py", line 1093, in _validate_conn
    conn.connect()
    ~~~~~~~~~~~~^^
  File "/lustrefs/disk/home/pjakkraw/workspace/eomt/.venv/lib/python3.13/site-packages/urllib3/connection.py", line 753, in connect
    self.sock = sock = self._new_conn()
                       ~~~~~~~~~~~~~~^^
  File "/lustrefs/disk/home/pjakkraw/workspace/eomt/.venv/lib/python3.13/site-packages/urllib3/connection.py", line 213, in _new_conn
    raise NewConnectionError(
        self, f"Failed to establish a new connection: {e}"
    ) from e
urllib3.exceptions.NewConnectionError: <urllib3.connection.HTTPSConnection object at 0x7fbe6e927610>: Failed to establish a new connection: [Errno 101] Network is unreachable

The above exception was the direct cause of the following exception:

Traceback (most recent call last):
  File "/lustrefs/disk/home/pjakkraw/workspace/eomt/.venv/lib/python3.13/site-packages/requests/adapters.py", line 644, in send
    resp = conn.urlopen(
        method=request.method,
    ...<9 lines>...
        chunked=chunked,
    )
  File "/lustrefs/disk/home/pjakkraw/workspace/eomt/.venv/lib/python3.13/site-packages/urllib3/connectionpool.py", line 841, in urlopen
    retries = retries.increment(
        method, url, error=new_e, _pool=self, _stacktrace=sys.exc_info()[2]
    )
  File "/lustrefs/disk/home/pjakkraw/workspace/eomt/.venv/lib/python3.13/site-packages/urllib3/util/retry.py", line 519, in increment
    raise MaxRetryError(_pool, url, reason) from reason  # type: ignore[arg-type]
    ^^^^^^^^^^^^^^^^^^^^^^^^^^^^^^^^^^^^^^^^^^^^^^^^^^^
urllib3.exceptions.MaxRetryError: HTTPSConnectionPool(host='huggingface.co', port=443): Max retries exceeded with url: /facebook/dinov3-vits16-pretrain-lvd1689m/resolve/main/config.json (Caused by NewConnectionError('<urllib3.connection.HTTPSConnection object at 0x7fbe6e927610>: Failed to establish a new connection: [Errno 101] Network is unreachable'))

During handling of the above exception, another exception occurred:

Traceback (most recent call last):
  File "/lustrefs/disk/home/pjakkraw/workspace/eomt/.venv/lib/python3.13/site-packages/huggingface_hub/file_download.py", line 1546, in _get_metadata_or_catch_error
    metadata = get_hf_file_metadata(
        url=url, proxies=proxies, timeout=etag_timeout, headers=headers, token=token, endpoint=endpoint
    )
  File "/lustrefs/disk/home/pjakkraw/workspace/eomt/.venv/lib/python3.13/site-packages/huggingface_hub/utils/_validators.py", line 114, in _inner_fn
    return fn(*args, **kwargs)
  File "/lustrefs/disk/home/pjakkraw/workspace/eomt/.venv/lib/python3.13/site-packages/huggingface_hub/file_download.py", line 1463, in get_hf_file_metadata
    r = _request_wrapper(
        method="HEAD",
    ...<5 lines>...
        timeout=timeout,
    )
  File "/lustrefs/disk/home/pjakkraw/workspace/eomt/.venv/lib/python3.13/site-packages/huggingface_hub/file_download.py", line 286, in _request_wrapper
    response = _request_wrapper(
        method=method,
    ...<2 lines>...
        **params,
    )
  File "/lustrefs/disk/home/pjakkraw/workspace/eomt/.venv/lib/python3.13/site-packages/huggingface_hub/file_download.py", line 309, in _request_wrapper
    response = http_backoff(method=method, url=url, **params)
  File "/lustrefs/disk/home/pjakkraw/workspace/eomt/.venv/lib/python3.13/site-packages/huggingface_hub/utils/_http.py", line 327, in http_backoff
    raise err
  File "/lustrefs/disk/home/pjakkraw/workspace/eomt/.venv/lib/python3.13/site-packages/huggingface_hub/utils/_http.py", line 308, in http_backoff
    response = session.request(method=method, url=url, **kwargs)
  File "/lustrefs/disk/home/pjakkraw/workspace/eomt/.venv/lib/python3.13/site-packages/requests/sessions.py", line 589, in request
    resp = self.send(prep, **send_kwargs)
  File "/lustrefs/disk/home/pjakkraw/workspace/eomt/.venv/lib/python3.13/site-packages/requests/sessions.py", line 703, in send
    r = adapter.send(request, **kwargs)
  File "/lustrefs/disk/home/pjakkraw/workspace/eomt/.venv/lib/python3.13/site-packages/huggingface_hub/utils/_http.py", line 95, in send
    return super().send(request, *args, **kwargs)
           ~~~~~~~~~~~~^^^^^^^^^^^^^^^^^^^^^^^^^^
  File "/lustrefs/disk/home/pjakkraw/workspace/eomt/.venv/lib/python3.13/site-packages/requests/adapters.py", line 677, in send
    raise ConnectionError(e, request=request)
requests.exceptions.ConnectionError: (MaxRetryError("HTTPSConnectionPool(host='huggingface.co', port=443): Max retries exceeded with url: /facebook/dinov3-vits16-pretrain-lvd1689m/resolve/main/config.json (Caused by NewConnectionError('<urllib3.connection.HTTPSConnection object at 0x7fbe6e927610>: Failed to establish a new connection: [Errno 101] Network is unreachable'))"), '(Request ID: 8da892b8-13f0-44e9-9d5c-4e0d72a5ee45)')

The above exception was the direct cause of the following exception:

Traceback (most recent call last):
  File "/lustrefs/disk/home/pjakkraw/workspace/eomt/.venv/lib/python3.13/site-packages/transformers/utils/hub.py", line 478, in cached_files
    hf_hub_download(
    ~~~~~~~~~~~~~~~^
        path_or_repo_id,
        ^^^^^^^^^^^^^^^^
    ...<10 lines>...
        local_files_only=local_files_only,
        ^^^^^^^^^^^^^^^^^^^^^^^^^^^^^^^^^^
    )
    ^
  File "/lustrefs/disk/home/pjakkraw/workspace/eomt/.venv/lib/python3.13/site-packages/huggingface_hub/utils/_validators.py", line 114, in _inner_fn
    return fn(*args, **kwargs)
  File "/lustrefs/disk/home/pjakkraw/workspace/eomt/.venv/lib/python3.13/site-packages/huggingface_hub/file_download.py", line 1010, in hf_hub_download
    return _hf_hub_download_to_cache_dir(
        # Destination
    ...<14 lines>...
        force_download=force_download,
    )
  File "/lustrefs/disk/home/pjakkraw/workspace/eomt/.venv/lib/python3.13/site-packages/huggingface_hub/file_download.py", line 1117, in _hf_hub_download_to_cache_dir
    _raise_on_head_call_error(head_call_error, force_download, local_files_only)
    ~~~~~~~~~~~~~~~~~~~~~~~~~^^^^^^^^^^^^^^^^^^^^^^^^^^^^^^^^^^^^^^^^^^^^^^^^^^^
  File "/lustrefs/disk/home/pjakkraw/workspace/eomt/.venv/lib/python3.13/site-packages/huggingface_hub/file_download.py", line 1661, in _raise_on_head_call_error
    raise LocalEntryNotFoundError(
    ...<3 lines>...
    ) from head_call_error
huggingface_hub.errors.LocalEntryNotFoundError: An error happened while trying to locate the file on the Hub and we cannot find the requested files in the local cache. Please check your connection and try again or make sure your Internet connection is on.

The above exception was the direct cause of the following exception:

Traceback (most recent call last):
  File "/lustrefs/disk/home/pjakkraw/workspace/eomt/main.py", line 183, in <module>
    cli_main()
    ~~~~~~~~^^
  File "/lustrefs/disk/home/pjakkraw/workspace/eomt/main.py", line 161, in cli_main
    LightningCLI(
    ~~~~~~~~~~~~^
        LightningModule,
        ^^^^^^^^^^^^^^^^
    ...<15 lines>...
        },
        ^^
    )
    ^
  File "/lustrefs/disk/home/pjakkraw/workspace/eomt/main.py", line 111, in __init__
    super().__init__(*args, **kwargs)
    ~~~~~~~~~~~~~~~~^^^^^^^^^^^^^^^^^
  File "/lustrefs/disk/home/pjakkraw/workspace/eomt/.venv/lib/python3.13/site-packages/lightning/pytorch/cli.py", line 394, in __init__
    self.instantiate_classes()
    ~~~~~~~~~~~~~~~~~~~~~~~~^^
  File "/lustrefs/disk/home/pjakkraw/workspace/eomt/.venv/lib/python3.13/site-packages/lightning/pytorch/cli.py", line 561, in instantiate_classes
    self.config_init = self.parser.instantiate_classes(self.config)
                       ~~~~~~~~~~~~~~~~~~~~~~~~~~~~~~~^^^^^^^^^^^^^
  File "/lustrefs/disk/home/pjakkraw/workspace/eomt/.venv/lib/python3.13/site-packages/jsonargparse/_deprecated.py", line 140, in patched_instantiate_classes
    cfg = self._unpatched_instantiate_classes(cfg, **kwargs)
  File "/lustrefs/disk/home/pjakkraw/workspace/eomt/.venv/lib/python3.13/site-packages/jsonargparse/_core.py", line 1254, in instantiate_classes
    cfg[subcommand] = subparser.instantiate_classes(cfg[subcommand], instantiate_groups=instantiate_groups)
                      ~~~~~~~~~~~~~~~~~~~~~~~~~~~~~^^^^^^^^^^^^^^^^^^^^^^^^^^^^^^^^^^^^^^^^^^^^^^^^^^^^^^^^
  File "/lustrefs/disk/home/pjakkraw/workspace/eomt/.venv/lib/python3.13/site-packages/jsonargparse/_deprecated.py", line 140, in patched_instantiate_classes
    cfg = self._unpatched_instantiate_classes(cfg, **kwargs)
  File "/lustrefs/disk/home/pjakkraw/workspace/eomt/.venv/lib/python3.13/site-packages/jsonargparse/_core.py", line 1245, in instantiate_classes
    parent[key] = component.instantiate_classes(value)
                  ~~~~~~~~~~~~~~~~~~~~~~~~~~~~~^^^^^^^
  File "/lustrefs/disk/home/pjakkraw/workspace/eomt/.venv/lib/python3.13/site-packages/jsonargparse/_typehints.py", line 625, in instantiate_classes
    value[num] = adapt_typehints(
                 ~~~~~~~~~~~~~~~^
        val,
        ^^^^
    ...<4 lines>...
        logger=self.logger,
        ^^^^^^^^^^^^^^^^^^^
    )
    ^
  File "/lustrefs/disk/home/pjakkraw/workspace/eomt/.venv/lib/python3.13/site-packages/jsonargparse/_typehints.py", line 846, in adapt_typehints
    raise_union_unexpected_value(sorted_subtypes, val, vals)
    ~~~~~~~~~~~~~~~~~~~~~~~~~~~~^^^^^^^^^^^^^^^^^^^^^^^^^^^^
  File "/lustrefs/disk/home/pjakkraw/workspace/eomt/main.py", line 44, in _raise_union
    raise e
  File "/lustrefs/disk/home/pjakkraw/workspace/eomt/.venv/lib/python3.13/site-packages/jsonargparse/_typehints.py", line 838, in adapt_typehints
    vals.append(adapt_typehints(val, subtype, **adapt_kwargs))
                ~~~~~~~~~~~~~~~^^^^^^^^^^^^^^^^^^^^^^^^^^^^^^
  File "/lustrefs/disk/home/pjakkraw/workspace/eomt/.venv/lib/python3.13/site-packages/jsonargparse/_typehints.py", line 1095, in adapt_typehints
    val = adapt_class_type(val, serialize, instantiate_classes, sub_add_kwargs, prev_val=prev_val)
  File "/lustrefs/disk/home/pjakkraw/workspace/eomt/.venv/lib/python3.13/site-packages/jsonargparse/_typehints.py", line 1403, in adapt_class_type
    init_args = parser.instantiate_classes(init_args)
  File "/lustrefs/disk/home/pjakkraw/workspace/eomt/.venv/lib/python3.13/site-packages/jsonargparse/_deprecated.py", line 140, in patched_instantiate_classes
    cfg = self._unpatched_instantiate_classes(cfg, **kwargs)
  File "/lustrefs/disk/home/pjakkraw/workspace/eomt/.venv/lib/python3.13/site-packages/jsonargparse/_core.py", line 1245, in instantiate_classes
    parent[key] = component.instantiate_classes(value)
                  ~~~~~~~~~~~~~~~~~~~~~~~~~~~~~^^^^^^^
  File "/lustrefs/disk/home/pjakkraw/workspace/eomt/.venv/lib/python3.13/site-packages/jsonargparse/_typehints.py", line 625, in instantiate_classes
    value[num] = adapt_typehints(
                 ~~~~~~~~~~~~~~~^
        val,
        ^^^^
    ...<4 lines>...
        logger=self.logger,
        ^^^^^^^^^^^^^^^^^^^
    )
    ^
  File "/lustrefs/disk/home/pjakkraw/workspace/eomt/.venv/lib/python3.13/site-packages/jsonargparse/_typehints.py", line 1095, in adapt_typehints
    val = adapt_class_type(val, serialize, instantiate_classes, sub_add_kwargs, prev_val=prev_val)
  File "/lustrefs/disk/home/pjakkraw/workspace/eomt/.venv/lib/python3.13/site-packages/jsonargparse/_typehints.py", line 1403, in adapt_class_type
    init_args = parser.instantiate_classes(init_args)
  File "/lustrefs/disk/home/pjakkraw/workspace/eomt/.venv/lib/python3.13/site-packages/jsonargparse/_deprecated.py", line 140, in patched_instantiate_classes
    cfg = self._unpatched_instantiate_classes(cfg, **kwargs)
  File "/lustrefs/disk/home/pjakkraw/workspace/eomt/.venv/lib/python3.13/site-packages/jsonargparse/_core.py", line 1245, in instantiate_classes
    parent[key] = component.instantiate_classes(value)
                  ~~~~~~~~~~~~~~~~~~~~~~~~~~~~~^^^^^^^
  File "/lustrefs/disk/home/pjakkraw/workspace/eomt/.venv/lib/python3.13/site-packages/jsonargparse/_typehints.py", line 625, in instantiate_classes
    value[num] = adapt_typehints(
                 ~~~~~~~~~~~~~~~^
        val,
        ^^^^
    ...<4 lines>...
        logger=self.logger,
        ^^^^^^^^^^^^^^^^^^^
    )
    ^
  File "/lustrefs/disk/home/pjakkraw/workspace/eomt/.venv/lib/python3.13/site-packages/jsonargparse/_typehints.py", line 1095, in adapt_typehints
    val = adapt_class_type(val, serialize, instantiate_classes, sub_add_kwargs, prev_val=prev_val)
  File "/lustrefs/disk/home/pjakkraw/workspace/eomt/.venv/lib/python3.13/site-packages/jsonargparse/_typehints.py", line 1417, in adapt_class_type
    return instantiator_fn(val_class, **{**init_args, **dict_kwargs})
  File "/lustrefs/disk/home/pjakkraw/workspace/eomt/.venv/lib/python3.13/site-packages/jsonargparse/_common.py", line 224, in __call__
    return default_class_instantiator(class_type, *args, **kwargs)
  File "/lustrefs/disk/home/pjakkraw/workspace/eomt/.venv/lib/python3.13/site-packages/jsonargparse/_common.py", line 213, in default_class_instantiator
    return class_type(*args, **kwargs)
  File "/lustrefs/disk/home/pjakkraw/workspace/eomt/models/vit.py", line 27, in __init__
    AutoModel.from_pretrained(
    ~~~~~~~~~~~~~~~~~~~~~~~~~^
        backbone_name,
        ^^^^^^^^^^^^^^
    ),
    ^
  File "/lustrefs/disk/home/pjakkraw/workspace/eomt/.venv/lib/python3.13/site-packages/transformers/models/auto/auto_factory.py", line 549, in from_pretrained
    config, kwargs = AutoConfig.from_pretrained(
                     ~~~~~~~~~~~~~~~~~~~~~~~~~~^
        pretrained_model_name_or_path,
        ^^^^^^^^^^^^^^^^^^^^^^^^^^^^^^
    ...<4 lines>...
        **kwargs,
        ^^^^^^^^^
    )
    ^
  File "/lustrefs/disk/home/pjakkraw/workspace/eomt/.venv/lib/python3.13/site-packages/transformers/models/auto/configuration_auto.py", line 1288, in from_pretrained
    config_dict, unused_kwargs = PretrainedConfig.get_config_dict(pretrained_model_name_or_path, **kwargs)
                                 ~~~~~~~~~~~~~~~~~~~~~~~~~~~~~~~~^^^^^^^^^^^^^^^^^^^^^^^^^^^^^^^^^^^^^^^^^
  File "/lustrefs/disk/home/pjakkraw/workspace/eomt/.venv/lib/python3.13/site-packages/transformers/configuration_utils.py", line 662, in get_config_dict
    config_dict, kwargs = cls._get_config_dict(pretrained_model_name_or_path, **kwargs)
                          ~~~~~~~~~~~~~~~~~~~~^^^^^^^^^^^^^^^^^^^^^^^^^^^^^^^^^^^^^^^^^
  File "/lustrefs/disk/home/pjakkraw/workspace/eomt/.venv/lib/python3.13/site-packages/transformers/configuration_utils.py", line 721, in _get_config_dict
    resolved_config_file = cached_file(
        pretrained_model_name_or_path,
    ...<10 lines>...
        _commit_hash=commit_hash,
    )
  File "/lustrefs/disk/home/pjakkraw/workspace/eomt/.venv/lib/python3.13/site-packages/transformers/utils/hub.py", line 321, in cached_file
    file = cached_files(path_or_repo_id=path_or_repo_id, filenames=[filename], **kwargs)
  File "/lustrefs/disk/home/pjakkraw/workspace/eomt/.venv/lib/python3.13/site-packages/transformers/utils/hub.py", line 552, in cached_files
    raise OSError(
    ...<3 lines>...
    ) from e
OSError: We couldn't connect to 'https://huggingface.co' to load the files, and couldn't find them in the cached files.
Check your internet connection or see how to run the library in offline mode at 'https://huggingface.co/docs/transformers/installation#offline-mode'.
