[rank: 0] Seed set to 0
'(MaxRetryError("HTTPSConnectionPool(host='huggingface.co', port=443): Max retries exceeded with url: /facebook/dinov3-vits16-pretrain-lvd1689m/resolve/main/config.json (Caused by NewConnectionError('<urllib3.connection.HTTPSConnection object at 0x7f0ea32f5fd0>: Failed to establish a new connection: [Errno 101] Network is unreachable'))"), '(Request ID: 6187b438-688c-43c3-849f-5795e918f16e)')' thrown while requesting HEAD https://huggingface.co/facebook/dinov3-vits16-pretrain-lvd1689m/resolve/main/config.json
Retrying in 1s [Retry 1/5].
'(MaxRetryError("HTTPSConnectionPool(host='huggingface.co', port=443): Max retries exceeded with url: /facebook/dinov3-vits16-pretrain-lvd1689m/resolve/main/config.json (Caused by NewConnectionError('<urllib3.connection.HTTPSConnection object at 0x7f0ea3305a90>: Failed to establish a new connection: [Errno 101] Network is unreachable'))"), '(Request ID: f71f248a-9600-48d2-984e-1a0b8fd2a03c)')' thrown while requesting HEAD https://huggingface.co/facebook/dinov3-vits16-pretrain-lvd1689m/resolve/main/config.json
Retrying in 2s [Retry 2/5].
'(MaxRetryError("HTTPSConnectionPool(host='huggingface.co', port=443): Max retries exceeded with url: /facebook/dinov3-vits16-pretrain-lvd1689m/resolve/main/config.json (Caused by NewConnectionError('<urllib3.connection.HTTPSConnection object at 0x7f0ea3305d10>: Failed to establish a new connection: [Errno 101] Network is unreachable'))"), '(Request ID: 5468b83e-553d-43f3-8dfd-d7074abb7813)')' thrown while requesting HEAD https://huggingface.co/facebook/dinov3-vits16-pretrain-lvd1689m/resolve/main/config.json
Retrying in 4s [Retry 3/5].
'(MaxRetryError("HTTPSConnectionPool(host='huggingface.co', port=443): Max retries exceeded with url: /facebook/dinov3-vits16-pretrain-lvd1689m/resolve/main/config.json (Caused by NewConnectionError('<urllib3.connection.HTTPSConnection object at 0x7f0ea3307390>: Failed to establish a new connection: [Errno 101] Network is unreachable'))"), '(Request ID: 7165bb32-4e6c-4cf6-9ac2-e327c99f6438)')' thrown while requesting HEAD https://huggingface.co/facebook/dinov3-vits16-pretrain-lvd1689m/resolve/main/config.json
Retrying in 8s [Retry 4/5].
'(MaxRetryError("HTTPSConnectionPool(host='huggingface.co', port=443): Max retries exceeded with url: /facebook/dinov3-vits16-pretrain-lvd1689m/resolve/main/config.json (Caused by NewConnectionError('<urllib3.connection.HTTPSConnection object at 0x7f0ea3306350>: Failed to establish a new connection: [Errno 101] Network is unreachable'))"), '(Request ID: a1c8b9ea-730e-492e-af91-ec160ff29e1d)')' thrown while requesting HEAD https://huggingface.co/facebook/dinov3-vits16-pretrain-lvd1689m/resolve/main/config.json
Retrying in 8s [Retry 5/5].
'(MaxRetryError("HTTPSConnectionPool(host='huggingface.co', port=443): Max retries exceeded with url: /facebook/dinov3-vits16-pretrain-lvd1689m/resolve/main/config.json (Caused by NewConnectionError('<urllib3.connection.HTTPSConnection object at 0x7f0ea3305810>: Failed to establish a new connection: [Errno 101] Network is unreachable'))"), '(Request ID: 9958188e-aa1b-4776-b06c-47ba215ae6e1)')' thrown while requesting HEAD https://huggingface.co/facebook/dinov3-vits16-pretrain-lvd1689m/resolve/main/config.json
Using 16bit Automatic Mixed Precision (AMP)
Using default `ModelCheckpoint`. Consider installing `litmodels` package to enable `LitModelCheckpoint` for automatic upload to the Lightning model registry.
GPU available: True (cuda), used: True
TPU available: False, using: 0 TPU cores
HPU available: False, using: 0 HPUs
wandb: Network error (ConnectionError), entering retry loop.
wandb: W&B API key is configured. Use `wandb login --relogin` to force relogin
wandb: Network error (ConnectionError), entering retry loop.
wandb: ERROR Run initialization has timed out after 90.0 sec. Please try increasing the timeout with the `init_timeout` setting: `wandb.init(settings=wandb.Settings(init_timeout=120))`.
Traceback (most recent call last):
  File "/home/pjakkraw/.local/share/uv/python/cpython-3.13.2-linux-x86_64-gnu/lib/python3.13/asyncio/tasks.py", line 507, in wait_for
    return await fut
           ^^^^^^^^^
  File "/home/pjakkraw/.local/share/uv/python/cpython-3.13.2-linux-x86_64-gnu/lib/python3.13/asyncio/locks.py", line 213, in wait
    await fut
asyncio.exceptions.CancelledError

The above exception was the direct cause of the following exception:

Traceback (most recent call last):
  File "/lustrefs/disk/home/pjakkraw/workspace/eomt/.venv/lib/python3.13/site-packages/wandb/sdk/mailbox/response_handle.py", line 109, in wait_async
    await asyncio.wait_for(evt.wait(), timeout=timeout)
  File "/home/pjakkraw/.local/share/uv/python/cpython-3.13.2-linux-x86_64-gnu/lib/python3.13/asyncio/tasks.py", line 506, in wait_for
    async with timeouts.timeout(timeout):
               ~~~~~~~~~~~~~~~~^^^^^^^^^
  File "/home/pjakkraw/.local/share/uv/python/cpython-3.13.2-linux-x86_64-gnu/lib/python3.13/asyncio/timeouts.py", line 116, in __aexit__
    raise TimeoutError from exc_val
TimeoutError

The above exception was the direct cause of the following exception:

Traceback (most recent call last):
  File "/lustrefs/disk/home/pjakkraw/workspace/eomt/.venv/lib/python3.13/site-packages/wandb/sdk/wandb_init.py", line 1052, in init
    result = wait_with_progress(
        run_init_handle,
    ...<2 lines>...
        display_progress=display_init_message,
    )
  File "/lustrefs/disk/home/pjakkraw/workspace/eomt/.venv/lib/python3.13/site-packages/wandb/sdk/mailbox/wait_with_progress.py", line 24, in wait_with_progress
    return wait_all_with_progress(
           ~~~~~~~~~~~~~~~~~~~~~~^
        [handle],
        ^^^^^^^^^
    ...<2 lines>...
        display_progress=display_progress,
        ^^^^^^^^^^^^^^^^^^^^^^^^^^^^^^^^^^
    )[0]
    ^
  File "/lustrefs/disk/home/pjakkraw/workspace/eomt/.venv/lib/python3.13/site-packages/wandb/sdk/mailbox/wait_with_progress.py", line 87, in wait_all_with_progress
    return asyncio_compat.run(progress_loop_with_timeout)
           ~~~~~~~~~~~~~~~~~~^^^^^^^^^^^^^^^^^^^^^^^^^^^^
  File "/lustrefs/disk/home/pjakkraw/workspace/eomt/.venv/lib/python3.13/site-packages/wandb/sdk/lib/asyncio_compat.py", line 30, in run
    return future.result()
           ~~~~~~~~~~~~~^^
  File "/home/pjakkraw/.local/share/uv/python/cpython-3.13.2-linux-x86_64-gnu/lib/python3.13/concurrent/futures/_base.py", line 456, in result
    return self.__get_result()
           ~~~~~~~~~~~~~~~~~^^
  File "/home/pjakkraw/.local/share/uv/python/cpython-3.13.2-linux-x86_64-gnu/lib/python3.13/concurrent/futures/_base.py", line 401, in __get_result
    raise self._exception
  File "/home/pjakkraw/.local/share/uv/python/cpython-3.13.2-linux-x86_64-gnu/lib/python3.13/concurrent/futures/thread.py", line 59, in run
    result = self.fn(*self.args, **self.kwargs)
  File "/lustrefs/disk/home/pjakkraw/workspace/eomt/.venv/lib/python3.13/site-packages/wandb/sdk/lib/asyncio_compat.py", line 74, in run
    return asyncio.run(self._run_or_cancel(fn))
           ~~~~~~~~~~~^^^^^^^^^^^^^^^^^^^^^^^^^
  File "/home/pjakkraw/.local/share/uv/python/cpython-3.13.2-linux-x86_64-gnu/lib/python3.13/asyncio/runners.py", line 195, in run
    return runner.run(main)
           ~~~~~~~~~~^^^^^^
  File "/home/pjakkraw/.local/share/uv/python/cpython-3.13.2-linux-x86_64-gnu/lib/python3.13/asyncio/runners.py", line 118, in run
    return self._loop.run_until_complete(task)
           ~~~~~~~~~~~~~~~~~~~~~~~~~~~~~^^^^^^
  File "/home/pjakkraw/.local/share/uv/python/cpython-3.13.2-linux-x86_64-gnu/lib/python3.13/asyncio/base_events.py", line 725, in run_until_complete
    return future.result()
           ~~~~~~~~~~~~~^^
  File "/lustrefs/disk/home/pjakkraw/workspace/eomt/.venv/lib/python3.13/site-packages/wandb/sdk/lib/asyncio_compat.py", line 98, in _run_or_cancel
    return fn_task.result()
           ~~~~~~~~~~~~~~^^
  File "/lustrefs/disk/home/pjakkraw/workspace/eomt/.venv/lib/python3.13/site-packages/wandb/sdk/mailbox/wait_with_progress.py", line 82, in progress_loop_with_timeout
    return await _wait_handles_async(
           ^^^^^^^^^^^^^^^^^^^^^^^^^^
    ...<2 lines>...
    )
    ^
  File "/lustrefs/disk/home/pjakkraw/workspace/eomt/.venv/lib/python3.13/site-packages/wandb/sdk/mailbox/wait_with_progress.py", line 130, in _wait_handles_async
    async with asyncio_compat.open_task_group() as task_group:
               ~~~~~~~~~~~~~~~~~~~~~~~~~~~~~~^^
  File "/home/pjakkraw/.local/share/uv/python/cpython-3.13.2-linux-x86_64-gnu/lib/python3.13/contextlib.py", line 221, in __aexit__
    await anext(self.gen)
  File "/lustrefs/disk/home/pjakkraw/workspace/eomt/.venv/lib/python3.13/site-packages/wandb/sdk/lib/asyncio_compat.py", line 190, in open_task_group
    await task_group._wait_all()
  File "/lustrefs/disk/home/pjakkraw/workspace/eomt/.venv/lib/python3.13/site-packages/wandb/sdk/lib/asyncio_compat.py", line 159, in _wait_all
    raise exc
  File "/lustrefs/disk/home/pjakkraw/workspace/eomt/.venv/lib/python3.13/site-packages/wandb/sdk/mailbox/wait_with_progress.py", line 128, in wait_single
    results[index] = await handle.wait_async(timeout=timeout)
                     ^^^^^^^^^^^^^^^^^^^^^^^^^^^^^^^^^^^^^^^^
  File "/lustrefs/disk/home/pjakkraw/workspace/eomt/.venv/lib/python3.13/site-packages/wandb/sdk/mailbox/mailbox_handle.py", line 126, in wait_async
    response = await self._handle.wait_async(timeout=timeout)
               ^^^^^^^^^^^^^^^^^^^^^^^^^^^^^^^^^^^^^^^^^^^^^^
  File "/lustrefs/disk/home/pjakkraw/workspace/eomt/.venv/lib/python3.13/site-packages/wandb/sdk/mailbox/response_handle.py", line 118, in wait_async
    raise TimeoutError(
        f"Timed out waiting for response on {self._address}"
    ) from e
TimeoutError: Timed out waiting for response on mmv3foif2zbp

During handling of the above exception, another exception occurred:

Traceback (most recent call last):
  File "/lustrefs/disk/home/pjakkraw/workspace/eomt/main.py", line 183, in <module>
    cli_main()
    ~~~~~~~~^^
  File "/lustrefs/disk/home/pjakkraw/workspace/eomt/main.py", line 161, in cli_main
    LightningCLI(
    ~~~~~~~~~~~~^
        LightningModule,
        ^^^^^^^^^^^^^^^^
    ...<15 lines>...
        },
        ^^
    )
    ^
  File "/lustrefs/disk/home/pjakkraw/workspace/eomt/main.py", line 111, in __init__
    super().__init__(*args, **kwargs)
    ~~~~~~~~~~~~~~~~^^^^^^^^^^^^^^^^^
  File "/lustrefs/disk/home/pjakkraw/workspace/eomt/.venv/lib/python3.13/site-packages/lightning/pytorch/cli.py", line 398, in __init__
    self._run_subcommand(self.subcommand)
    ~~~~~~~~~~~~~~~~~~~~^^^^^^^^^^^^^^^^^
  File "/lustrefs/disk/home/pjakkraw/workspace/eomt/.venv/lib/python3.13/site-packages/lightning/pytorch/cli.py", line 708, in _run_subcommand
    fn(**fn_kwargs)
    ~~^^^^^^^^^^^^^
  File "/lustrefs/disk/home/pjakkraw/workspace/eomt/main.py", line 143, in fit
    if hasattr(self.trainer.logger.experiment, "log_code"):
               ^^^^^^^^^^^^^^^^^^^^^^^^^^^^^^
  File "/lustrefs/disk/home/pjakkraw/workspace/eomt/.venv/lib/python3.13/site-packages/lightning/fabric/loggers/logger.py", line 118, in experiment
    return fn(self)
  File "/lustrefs/disk/home/pjakkraw/workspace/eomt/.venv/lib/python3.13/site-packages/lightning/pytorch/loggers/wandb.py", line 407, in experiment
    self._experiment = wandb.init(**self._wandb_init)
                       ~~~~~~~~~~^^^^^^^^^^^^^^^^^^^^
  File "/lustrefs/disk/home/pjakkraw/workspace/eomt/.venv/lib/python3.13/site-packages/wandb/sdk/wandb_init.py", line 1664, in init
    wandb._sentry.reraise(e)
    ~~~~~~~~~~~~~~~~~~~~~^^^
  File "/lustrefs/disk/home/pjakkraw/workspace/eomt/.venv/lib/python3.13/site-packages/wandb/analytics/sentry.py", line 156, in reraise
    raise exc.with_traceback(sys.exc_info()[2])
  File "/lustrefs/disk/home/pjakkraw/workspace/eomt/.venv/lib/python3.13/site-packages/wandb/sdk/wandb_init.py", line 1650, in init
    return wi.init(run_settings, run_config, run_printer)
           ~~~~~~~^^^^^^^^^^^^^^^^^^^^^^^^^^^^^^^^^^^^^^^
  File "/lustrefs/disk/home/pjakkraw/workspace/eomt/.venv/lib/python3.13/site-packages/wandb/sdk/wandb_init.py", line 1065, in init
    raise CommError(
    ...<3 lines>...
    )
wandb.errors.errors.CommError: Run initialization has timed out after 90.0 sec. Please try increasing the timeout with the `init_timeout` setting: `wandb.init(settings=wandb.Settings(init_timeout=120))`.
slurmstepd: error: *** JOB 3040417 ON lanta-g-014 CANCELLED AT 2025-10-01T00:37:23 ***
